Workbook
Name PEG가격유형코드: [1]항목별참고값!$AD$2:$AD$5
Name REPO분류코드: [1]항목별참고값!$AQ$2:$AQ$5
Name Repo호가: [1]항목별참고값!$A$7
Name testtest: #REF!
Name testtest: #REF!
Name testtest: #REF!
Name testtest: #REF!
Name 거래정지발생유형코드: [1]항목별참고값!$P$2:$P$9
Name 계좌구분코드: [1]항목별참고값!$Y$2:$Y$20
Name 계좌증거금유형코드: [1]항목별참고값!$AL$2:$AL$8
Name 국가코드: [1]항목별참고값!$AM$2:$AM$5
Name 매도매수구분코드: [1]항목별참고값!$T$2:$T$5
Name 매도유형코드: [1]항목별참고값!$AI$2:$AI$6
Name 보드ID: [1]항목별참고값!$D$2:$D$24
Name 보드이벤트ID: [1]항목별참고값!$F$2:$F$69
Name 보드이벤트장운영종류코드: [1]항목별참고값!$K$2:$K$6
Name 보드이벤트적용군관계코드: [1]항목별참고값!$I$2:$I$4
Name 보드이벤트종류코드: [1]항목별참고값!$J$2:$J$24
Name 복합호가: [1]항목별참고값!$A$4
Name 상품ID: [1]항목별참고값!$O$2:$O$100
Name 세션ID: [1]항목별참고값!$N$2:$N$19
Name 세션개시종료코드: [1]항목별참고값!$M$2:$M$8
Name 수신IF유형코드: [1]항목별참고값!$S$2:$S$4
Name 시가종가산출코드: [1]항목별참고값!$L$2:$L$4
Name 시장ID: [1]항목별참고값!$C$2:$C$9
Name 여부: [1]항목별참고값!$AE$2:$AE$4
Name 외국인투자자구분코드: [1]항목별참고값!$AN$2:$AN$9
Name 위탁자기구분코드: [1]항목별참고값!$X$2:$X$9
Name 입력데이터종류: [1]항목별참고값!$A$2:$A$7
Name 자동취소처리구분코드: [1]항목별참고값!$R$2:$R$5
Name 장운영: [1]항목별참고값!$A$2
Name 장운영상품그룹ID: [1]항목별참고값!$E$2:$E$24
Name 정정취소구분코드: [1]항목별참고값!$U$2:$U$5
Name 주문매체구분코드: [1]항목별참고값!$AB$2:$AB$8
Name 채권일반호가: [1]항목별참고값!$A$5
Name 채권조성호가: [1]항목별참고값!$A$6
Name 채권호가종류코드: [1]항목별참고값!$AC$2:$AC$4
Name 테이블목록범위: #REF!
Name 테이블목록범위: #REF!
Name 테이블목록범위: #REF!
Name 테이블목록범위: #REF!
Name 테이블목록범위2: #REF!
Name 테이블목록범위2: #REF!
Name 테이블목록범위2: #REF!
Name 테이블목록범위2: #REF!
Name 투자자구분코드: [1]항목별참고값!$Z$2:$Z$12
Name 프로그램호가신고구분코드: [1]항목별참고값!$AO$2:$AO$5
Name 호가: [1]항목별참고값!$A$3
Name 호가유형코드: [1]항목별참고값!$V$2:$V$12
Name 호가일자: [1]항목별참고값!$AA$2
Name 호가조건코드: [1]항목별참고값!$W$2:$W$10
Name 효력정지재개구분코드: [1]항목별참고값!$AP$2:$AP$7

Sheet 표지

Sheet 변경이력(FTP)
B2: 인터페이스 변경이력
B4: 버전 | C4: 날짜 | D4: 변경내용 | E4: 정보상품 | F4: 비고
B5: 1.00 | C5: 44463 | D5: □ 최초작성 | F5: 지수별송신처 - 지수ID, 표준코드 공란(TBD)은 추후 공지 예정
B6: 1.01 | C6: 44575 | D6: □ 항목 길이 조정 □ 항목명 수정 □ 지수별송신처 - 지수ID, 표준코드 추가
B7: 1.02 | C7: 44630 | D7: □ 인터페이스목록 - 채권지수, 글로벌지수, 한대만IT프리미어지수, ELW투자지표 TR코드 수정 □ IA000, IB000, J2000, Z5000, Z4000 필러 추가 □ 100M 상품 미가동에 대한 변경 : 송신채널정보 삭제 - 미가동 상품 : 증권A, 증권B, 증권C ※ 일부가동 상품(부산만 제공) : 파생A, 파생B □ 소수점자리수: 데이터에 소수점 포함인 경우 0으로 하고 비고에 데이터형태 표시, 포함되지 않는 경우 소수점자리수 표시 □ 인터넷(TCP) 시세상품별 송신채널정보 탭 추가 □ IFMIBAT1035 Filler추가
B8: 1.03 | C8: 44630 | D8: □ 소수점표현 정보분배 접속표준서 형태로 정리 □ 신규 지수 추가
B9: 1.04 | C9: 44666 | D9: □ 지수ID 변경 (지수별송신처(IP_PORT매핑) 지수ID 부분에 노란색으로 표시) □ KTB채권지수 항목명 지수ID->채권지수ID로 변경 (채권지수ID는 지수ID체계를 따르지 않음) □ 지수별송신처(IP_PORT매핑) 탭에 기존 TR코드 추가
B10: 1.05 | C10: 44708 | D10: □ 지수별송신처(FTP종가) 탭 삭제 - 코드값모음집 - 상품별 지수목록 (FTP종가) 에 상품별 지수 제공
B11: 1.06 | C11: 44750 | D11: □ 인터페이스목록 - 주식파생대상종목시세 12M/100M 통합 □ 인터페이스정의서 - 정의 수정 | F11: 변경내역 노란색 음영 표시
B12: 1.07 | C12: 44841 | D12: □ 인터페이스목록, 인터페이스 정의서 - IFMIBAT1034 (MPBJC100) 삭제 □ FTP종가 파일 - 데이터구분값 정의 수정 | F12: 변경내역 노란색 음영 표시

Sheet 인터페이스목록
B1: 인터페이스 ID (링크) | C1: 인터페이스 명 (전문명) | D1: 송수신 방법 | E1: 업무 상세 내용 | F1: 제공 주기 | G1: TR-CODE | H1: 온라인 배치 구분 | I1: 시장구분 | Y1: 길이 | Z1: 비고 | AA1: 인터페이스 정의서 | AB1: 인터페이스 정의서
J2: Information Products
J3: 회원사/정보이용사 | K3: 증권A/100M·12M | L3: 증권A/128K | M3: 주식파생대상종목시세/100M·12M | N3: 증권B/100M·12M | O3: 증권B/128K | P3: 증권C/100M·12M(ELW회선) | Q3: 채권A/8M | R3: 채권A/512K | S3: 채권A/128K | T3: 일반상품/100M·12M | U3: 그룹1(지수상품1) | V3: 그룹2(지수상품2) | W3: 그룹3(지수상품3) | X3: 인터넷분배 | AA3: 인터페이스 정의서 | AB3: 인터페이스 정의서
A5: =ROW()-4 -> 1 | B5: =HYPERLINK("#"&ADDRESS(MATCH($AB5,인터페이스정의서!$A:$A, 0), 1,,,"인터페이스정의서"), $AB5) -> IFMIBAT1003 | C5: 레버리지지수종가 | D5: SFTP | E5: 레버리지 KOSPI200 지수 | F5: 0.67361111 | G5: MPBJC014 | H5: B | I5: ALL | J5: ● | Y5: 120 | Z5: 코드값모음집_차세대 - 상품별 지수목록(FTP종가) 참고 | AA5: =HYPERLINK("#"&ADDRESS(MATCH($B5,인터페이스정의서!$A:$A, 0), 1,,,"인터페이스정의서"), "이동") -> 이동 | AB5: IFMIBAT1003
A6: =ROW()-4 -> 2 | B6: =HYPERLINK("#"&ADDRESS(MATCH($AB6,인터페이스정의서!$A:$A, 0), 1,,,"인터페이스정의서"), $AB6) -> IFMIBAT1004 | C6: KRX지수 현물 정규장 | D6: SFTP | E6: KRX1차현물지수종가파일(KRX지수정보 FTP상품화) | F6: 0.67361111 | G6: MPBJC029 | H6: B | I6: ALL | J6: ● | Y6: 120 | Z6: 코드값모음집_차세대 - 상품별 지수목록(FTP종가) 참고 | AA6: =HYPERLINK("#"&ADDRESS(MATCH($B6,인터페이스정의서!$A:$A, 0), 1,,,"인터페이스정의서"), "이동") -> 이동 | AB6: IFMIBAT1004
A7: =ROW()-4 -> 3 | B7: =HYPERLINK("#"&ADDRESS(MATCH($AB7,인터페이스정의서!$A:$A, 0), 1,,,"인터페이스정의서"), $AB7) -> IFMIBAT1005 | C7: KRX지수 레버리지지수 | D7: SFTP | E7: 레버리지 KOSPI200 지수(KRX지수정보 FTP상품화) | F7: 0.67361111 | G7: MPBJC031 | H7: B | I7: ALL | J7: ● | Y7: 120 | Z7: 코드값모음집_차세대 - 상품별 지수목록(FTP종가) 참고 | AA7: =HYPERLINK("#"&ADDRESS(MATCH($B7,인터페이스정의서!$A:$A, 0), 1,,,"인터페이스정의서"), "이동") -> 이동 | AB7: IFMIBAT1005
A8: =ROW()-4 -> 4 | B8: =HYPERLINK("#"&ADDRESS(MATCH($AB8,인터페이스정의서!$A:$A, 0), 1,,,"인터페이스정의서"), $AB8) -> IFMIBAT1006 | C8: KRX지수 특수지수 1차 | D8: SFTP | E8: KRX지수 특수지수 1차 종가파일(KRX지수정보 FTP상품화 | F8: 0.67361111 | G8: MPBJC039 | H8: B | I8: ALL | J8: ● | Y8: 120 | Z8: 코드값모음집_차세대 - 상품별 지수목록(FTP종가) 참고 | AA8: =HYPERLINK("#"&ADDRESS(MATCH($B8,인터페이스정의서!$A:$A, 0), 1,,,"인터페이스정의서"), "이동") -> 이동 | AB8: IFMIBAT1006
A9: =ROW()-4 -> 5 | B9: =HYPERLINK("#"&ADDRESS(MATCH($AB9,인터페이스정의서!$A:$A, 0), 1,,,"인터페이스정의서"), $AB9) -> IFMIBAT1007 | C9: KRX지수 배당관련지수 1차 | D9: SFTP | E9: KRX지수 배당관련지수 1차 종가파일(KRX지수정보 FTP상품화 | F9: 0.67361111 | G9: MPBJC042 | H9: B | I9: ALL | J9: ● | Y9: 120 | Z9: 코드값모음집_차세대 - 상품별 지수목록(FTP종가) 참고 | AA9: =HYPERLINK("#"&ADDRESS(MATCH($B9,인터페이스정의서!$A:$A, 0), 1,,,"인터페이스정의서"), "이동") -> 이동 | AB9: IFMIBAT1007
A10: =ROW()-4 -> 6 | B10: =HYPERLINK("#"&ADDRESS(MATCH($AB10,인터페이스정의서!$A:$A, 0), 1,,,"인터페이스정의서"), $AB10) -> IFMIBAT1009 | C10: 금현물지수 | D10: SFTP | E10: KRX_금현물지수종가 | F10: 0.67361111 | G10: MPBJC046 | H10: B | I10: ALL | J10: ● | Y10: 120 | Z10: 코드값모음집_차세대 - 상품별 지수목록(FTP종가) 참고 | AA10: =HYPERLINK("#"&ADDRESS(MATCH($B10,인터페이스정의서!$A:$A, 0), 1,,,"인터페이스정의서"), "이동") -> 이동 | AB10: IFMIBAT1009
A11: =ROW()-4 -> 7 | B11: =HYPERLINK("#"&ADDRESS(MATCH($AB11,인터페이스정의서!$A:$A, 0), 1,,,"인터페이스정의서"), $AB11) -> IFMIBAT1012 | C11: KRX지수 현물 전체장 | D11: SFTP | E11: KRX2차현물지수종가파일(KRX지수정보 FTP상품화) | F11: 0.75694444 | G11: MPBJC030 | H11: B | I11: ALL | J11: ● | Y11: 120 | Z11: 코드값모음집_차세대 - 상품별 지수목록(FTP종가) 참고 | AA11: =HYPERLINK("#"&ADDRESS(MATCH($B11,인터페이스정의서!$A:$A, 0), 1,,,"인터페이스정의서"), "이동") -> 이동 | AB11: IFMIBAT1012
A12: =ROW()-4 -> 8 | B12: =HYPERLINK("#"&ADDRESS(MATCH($AB12,인터페이스정의서!$A:$A, 0), 1,,,"인터페이스정의서"), $AB12) -> IFMIBAT1013 | C12: KRX지수 특수지수 2차 | D12: SFTP | E12: KRX지수 특수지수 2차 종가파일(KRX지수정보 FTP상품화 | F12: 0.75694444 | G12: MPBJC040 | H12: B | I12: ALL | J12: ● | Y12: 120 | Z12: 코드값모음집_차세대 - 상품별 지수목록(FTP종가) 참고 | AA12: =HYPERLINK("#"&ADDRESS(MATCH($B12,인터페이스정의서!$A:$A, 0), 1,,,"인터페이스정의서"), "이동") -> 이동 | AB12: IFMIBAT1013
A13: =ROW()-4 -> 9 | B13: =HYPERLINK("#"&ADDRESS(MATCH($AB13,인터페이스정의서!$A:$A, 0), 1,,,"인터페이스정의서"), $AB13) -> IFMIBAT1014 | C13: KRX지수 배당관련지수 2차 | D13: SFTP | E13: KRX지수 배당관련지수 2차 종가파일(KRX지수정보 FTP상품화 | F13: 0.75694444 | G13: MPBJC043 | H13: B | I13: ALL | J13: ● | Y13: 120 | Z13: 코드값모음집_차세대 - 상품별 지수목록(FTP종가) 참고 | AA13: =HYPERLINK("#"&ADDRESS(MATCH($B13,인터페이스정의서!$A:$A, 0), 1,,,"인터페이스정의서"), "이동") -> 이동 | AB13: IFMIBAT1014
A14: =ROW()-4 -> 10 | B14: =HYPERLINK("#"&ADDRESS(MATCH($AB14,인터페이스정의서!$A:$A, 0), 1,,,"인터페이스정의서"), $AB14) -> IFMIBAT1017 | C14: KRX지수 파생 | D14: SFTP | E14: KRX특수지수종가파일(KRX지수정보 FTP상품화) | F14: 0.72916667 | G14: MPBJC032 | H14: B | I14: ALL | J14: ● | Y14: 120 | Z14: 코드값모음집_차세대 - 상품별 지수목록(FTP종가) 참고 | AA14: =HYPERLINK("#"&ADDRESS(MATCH($B14,인터페이스정의서!$A:$A, 0), 1,,,"인터페이스정의서"), "이동") -> 이동 | AB14: IFMIBAT1017
A15: =ROW()-4 -> 11 | B15: =HYPERLINK("#"&ADDRESS(MATCH($AB15,인터페이스정의서!$A:$A, 0), 1,,,"인터페이스정의서"), $AB15) -> IFMIBAT1018 | C15: KRX_ETN지수 파생 | D15: SFTP | E15: KRX_ETN 특수지수종가파일(KRX지수정보 FTP상품화) | F15: 0.72916667 | G15: MPBJC044 | H15: B | I15: ALL | J15: ● | Y15: 120 | Z15: 코드값모음집_차세대 - 상품별 지수목록(FTP종가) 참고 | AA15: =HYPERLINK("#"&ADDRESS(MATCH($B15,인터페이스정의서!$A:$A, 0), 1,,,"인터페이스정의서"), "이동") -> 이동 | AB15: IFMIBAT1018
A16: =ROW()-4 -> 12 | B16: =HYPERLINK("#"&ADDRESS(MATCH($AB16,인터페이스정의서!$A:$A, 0), 1,,,"인터페이스정의서"), $AB16) -> IFMIBAT1019 | C16: 코스피옵션양매도지수 종가 | D16: SFTP | E16: 코스피옵션양매도지수 종가파일 | F16: 0.72916667 | G16: MPBJC047 | H16: B | I16: ALL | J16: ● | Y16: 120 | Z16: 코드값모음집_차세대 - 상품별 지수목록(FTP종가) 참고 | AA16: =HYPERLINK("#"&ADDRESS(MATCH($B16,인터페이스정의서!$A:$A, 0), 1,,,"인터페이스정의서"), "이동") -> 이동 | AB16: IFMIBAT1019
... A22: =ROW()-4 -> 18 | B22: =HYPERLINK("#"&ADDRESS(MATCH($AB22,인터페이스정의서!$A:$A, 0), 1,,,"인터페이스정의서"), $AB22) -> IFMIBAT1025 | C22: 지수그룹3 미래에셋 FTP종가 | D22: SFTP | E22: 지수그룹3 미래에셋 FTP종가파일 | F22: 0.72916667 | G22: MPBJC061 | H22: B | I22: ALL | J22: ● | Y22: 36 | Z22: 코드값모음집_차세대 - 상품별 지수목록(FTP종가) 참고 | AA22: =HYPERLINK("#"&ADDRESS(MATCH($B22,인터페이스정의서!$A:$A, 0), 1,,,"인터페이스정의서"), "이동") -> 이동 | AB22: IFMIBAT1025
A23: =ROW()-4 -> 19 | B23: =HYPERLINK("#"&ADDRESS(MATCH($AB23,인터페이스정의서!$A:$A, 0), 1,,,"인터페이스정의서"), $AB23) -> IFMIBAT1026 | C23: 글로벌지수_Exchange지수 | D23: SFTP | E23: 글로벌지수_Exchange지수 | F23: 0.35416667 | G23: MPBJC033 | H23: B | I23: ALL | J23: ● | Y23: 120 | AA23: =HYPERLINK("#"&ADDRESS(MATCH($B23,인터페이스정의서!$A:$A, 0), 1,,,"인터페이스정의서"), "이동") -> 이동 | AB23: IFMIBAT1026
A24: =ROW()-4 -> 20 | B24: =HYPERLINK("#"&ADDRESS(MATCH($AB24,인터페이스정의서!$A:$A, 0), 1,,,"인터페이스정의서"), $AB24) -> IFMIBAT1027 | C24: 글로벌지수_Asia100+Exchange지수 | D24: SFTP | E24: 글로벌지수_Asia100+Exchange지수 | F24: 0.8125 | G24: MPBJC034 | H24: B | I24: ALL | J24: ● | Y24: 120 | AA24: =HYPERLINK("#"&ADDRESS(MATCH($B24,인터페이스정의서!$A:$A, 0), 1,,,"인터페이스정의서"), "이동") -> 이동 | AB24: IFMIBAT1027
A25: =ROW()-4 -> 21 | B25: =HYPERLINK("#"&ADDRESS(MATCH($AB25,인터페이스정의서!$A:$A, 0), 1,,,"인터페이스정의서"), $AB25) -> IFMIBAT1028 | C25: KTB지수 최종종가_FTP종가 | D25: SFTP | E25: KTB지수_FTP종가 | F25: 0.75694444 | G25: MPBJC035 | H25: B | I25: ALL | J25: ● | Y25: 115 | AA25: =HYPERLINK("#"&ADDRESS(MATCH($B25,인터페이스정의서!$A:$A, 0), 1,,,"인터페이스정의서"), "이동") -> 이동 | AB25: IFMIBAT1028
A26: =ROW()-4 -> 22 | B26: =HYPERLINK("#"&ADDRESS(MATCH($AB26,인터페이스정의서!$A:$A, 0), 1,,,"인터페이스정의서"), $AB26) -> IFMIBAT1029 | C26: 프라임지수 최종종가_FTP종가 | D26: SFTP | E26: 프라임지수 최종종가_FTP종가 파일 생성 후 MPBJC013_1 + MPBJC035 파일 병합 후 전송 | F26: 0.75694444 | G26: MPBJC035 | H26: B | I26: ALL | J26: ● | Y26: 190 | AA26: =HYPERLINK("#"&ADDRESS(MATCH($B26,인터페이스정의서!$A:$A, 0), 1,,,"인터페이스정의서"), "이동") -> 이동 | AB26: IFMIBAT1029
A27: =ROW()-4 -> 23 | B27: =HYPERLINK("#"&ADDRESS(MATCH($AB27,인터페이스정의서!$A:$A, 0), 1,,,"인터페이스정의서"), $AB27) -> IFMIBAT1030 | C27: 커스텀지수 FTP종가 | D27: SFTP | E27: 커스텀지수 FTP종가 | F27: 0.75694444 | G27: MPBJC048 | H27: B | I27: ALL | J27: ● | Y27: 36 | Z27: 코드값모음집_차세대 - 상품별 지수목록(FTP종가) 참고 | AA27: =HYPERLINK("#"&ADDRESS(MATCH($B27,인터페이스정의서!$A:$A, 0), 1,,,"인터페이스정의서"), "이동") -> 이동 | AB27: IFMIBAT1030
A28: =ROW()-4 -> 24 | B28: =HYPERLINK("#"&ADDRESS(MATCH($AB28,인터페이스정의서!$A:$A, 0), 1,,,"인터페이스정의서"), $AB28) -> IFMIBAT1031 | C28: 커스텀지수 부가정보 FTP종가_x000D_ (예탁원,한국자산평가, NICE피앤아이) | D28: SFTP | E28: 커스텀지수 부가정보 FTP종가_x000D_ (예탁원,한국자산평가, NICE피앤아이) | F28: 0.75694444 | G28: MPBJC055 | H28: B | I28: ALL | J28: ● | Y28: 195 | Z28: 코드값모음집_차세대 - 상품별 지수목록(FTP종가) 참고 | AA28: =HYPERLINK("#"&ADDRESS(MATCH($B28,인터페이스정의서!$A:$A, 0), 1,,,"인터페이스정의서"), "이동") -> 이동 | AB28: IFMIBAT1031
A29: =ROW()-4 -> 25 | B29: =HYPERLINK("#"&ADDRESS(MATCH($AB29,인터페이스정의서!$A:$A, 0), 1,,,"인터페이스정의서"), $AB29) -> IFMIBAT1032 | C29: 한ㆍ대만 IT프리미어지수 FTP종가 | D29: SFTP | E29: 한ㆍ대만 IT프리미어지수 FTP종가 FIA_ID_EmKrTwITPrmIdx + 럄_id_CbGnNewDealIdx 파일 머지 후 전송 | F29: 0.8125 | G29: MPBJC049 | H29: B | I29: ALL | J29: ● | Y29: 39 | AA29: =HYPERLINK("#"&ADDRESS(MATCH($B29,인터페이스정의서!$A:$A, 0), 1,,,"인터페이스정의서"), "이동") -> 이동 | AB29: IFMIBAT1032
A30: =ROW()-4 -> 26 | B30: =HYPERLINK("#"&ADDRESS(MATCH($AB30,인터페이스정의서!$A:$A, 0), 1,,,"인터페이스정의서"), $AB30) -> IFMIBAT1033 | C30: 한ㆍ대만 IT프리미어지수 휴일 FTP종가 | D30: SFTP | E30: 한ㆍ대만 IT프리미어지수 휴일 FTP종가 FIA_ID_KorTwnITPrmIdx 파일 bypass | F30: 0.35416667 | G30: MPBJC050 | H30: B | I30: ALL | J30: ● | Y30: 39 | AA30: =HYPERLINK("#"&ADDRESS(MATCH($B30,인터페이스정의서!$A:$A, 0), 1,,,"인터페이스정의서"), "이동") -> 이동 | AB30: IFMIBAT1033
A31: =ROW()-4 -> 27 | B31: =HYPERLINK("#"&ADDRESS(MATCH($AB31,인터페이스정의서!$A:$A, 0), 1,,,"인터페이스정의서"), $AB31) -> IFMIBAT1035 | C31: KTB지수_FTP종가 (예탁원) | D31: SFTP | E31: KTB지수_FTP종가 | F31: 0.75694444 | G31: MPBJC013_1 | H31: B | I31: ALL | J31: ● | Y31: 115 | AA31: =HYPERLINK("#"&ADDRESS(MATCH($B31,인터페이스정의서!$A:$A, 0), 1,,,"인터페이스정의서"), "이동") -> 이동 | AB31: IFMIBAT1035
A32: =ROW()-4 -> 28 | B32: =HYPERLINK("#"&ADDRESS(MATCH($AB32,인터페이스정의서!$A:$A, 0), 1,,,"인터페이스정의서"), $AB32) -> IFMIBAT1036 | C32: KRX통합USD지수 | D32: SFTP | E32: KRX 한중공동지수 USD 3종 | F32: 0.6875 | G32: MPBJC064 | H32: B | I32: ALL | J32: ● | Y32: 120 | Z32: 코드값모음집_차세대 - 상품별 지수목록(FTP종가) 참고 | AA32: =HYPERLINK("#"&ADDRESS(MATCH($B32,인터페이스정의서!$A:$A, 0), 1,,,"인터페이스정의서"), "이동") -> 이동 | AB32: IFMIBAT1036
A33: =ROW()-4 -> 29 | B33: =HYPERLINK("#"&ADDRESS(MATCH($AB33,인터페이스정의서!$A:$A, 0), 1,,,"인터페이스정의서"), $AB33) -> IFMIBAT1037 | C33: 한중공동지수종가 | D33: SFTP | E33: KRX CSI 한중공동지수 3종 | F33: 0.75 | G33: MPBJC065 | H33: B | I33: ALL | J33: ● | Y33: 120 | Z33: 코드값모음집_차세대 - 상품별 지수목록(FTP종가) 참고 | AA33: =HYPERLINK("#"&ADDRESS(MATCH($B33,인터페이스정의서!$A:$A, 0), 1,,,"인터페이스정의서"), "이동") -> 이동 | AB33: IFMIBAT1037

Sheet 인터페이스정의서
A1: 인터페이스ID | B1: 인터페이스명 | C1: 순번 | D1: 항목명 | E1: 소수점 이하 자릿수 | F1: 자료형 | G1: 길이 | H1: 변경 내역 | I1: 기존 길이 | J1: 누적 길이 | K1: 정의 | L1: 비고 | M1: 정보 이용사
A3: IFMIBAT1003 | B3: 레버리지지수종가 | C3: 1 | D3: 데이터구분값 | E3: 0 | F3: String | G3: 2 | J3: 2 | K3: A5 | M3: ●
A4: IFMIBAT1003 | B4: 레버리지지수종가 | C4: 2 | D4: 시장지수구분코드 | E4: 0 | F4: String | G4: 1 | J4: 3 | K4: 0 | M4: ●
A5: IFMIBAT1003 | B5: 레버리지지수종가 | C5: 3 | D5: 일련번호 | E5: 0 | F5: Int | G5: 5 | J5: 8 | M5: ●
A6: IFMIBAT1003 | B6: 레버리지지수종가 | C6: 4 | D6: 영업일자 | E6: 0 | F6: String | G6: 8 | J6: 16 | M6: ●
A7: IFMIBAT1003 | B7: 레버리지지수종가 | C7: 5 | D7: 지수ID | E7: 0 | F7: String | G7: 6 | H7: 신규 | J7: 22 | K7: 6자리 체계의 지수ID | M7: ●
A8: IFMIBAT1003 | B8: 레버리지지수종가 | C8: 6 | D8: 단순주가평균 | E8: 0 | F8: Int | G8: 6 | J8: 28 | M8: ●
A9: IFMIBAT1003 | B9: 레버리지지수종가 | C9: 7 | D9: 가중주가평균 | E9: 0 | F9: Int | G9: 6 | J9: 34 | M9: ●
A10: IFMIBAT1003 | B10: 레버리지지수종가 | C10: 8 | D10: 시가지수 | E10: 0 | F10: Double | G10: 8 | J10: 42 | K10: 9(6)V9(2) | M10: ●
A11: IFMIBAT1003 | B11: 레버리지지수종가 | C11: 9 | D11: 고가지수 | E11: 0 | F11: Double | G11: 8 | J11: 50 | K11: 9(6)V9(2) | M11: ●
A12: IFMIBAT1003 | B12: 레버리지지수종가 | C12: 10 | D12: 저가지수 | E12: 0 | F12: Double | G12: 8 | J12: 58 | K12: 9(6)V9(2) | M12: ●
A13: IFMIBAT1003 | B13: 레버리지지수종가 | C13: 11 | D13: 종가지수 | E13: 0 | F13: Double | G13: 8 | J13: 66 | K13: 9(6)V9(2) | M13: ●
A14: IFMIBAT1003 | B14: 레버리지지수종가 | C14: 12 | D14: 전일지수 | E14: 0 | F14: Double | G14: 8 | J14: 74 | K14: 9(6)V9(2) | M14: ●
A15: IFMIBAT1003 | B15: 레버리지지수종가 | C15: 13 | D15: 체결수량 | E15: 0 | F15: Int | G15: 8 | J15: 82 | M15: ●
A16: IFMIBAT1003 | B16: 레버리지지수종가 | C16: 14 | D16: 누적거래대금 | E16: 0 | F16: Long | G16: 12 | J16: 94 | M16: ●
A17: IFMIBAT1003 | B17: 레버리지지수종가 | C17: 15 | D17: 상장주식수 | E17: 0 | F17: Int | G17: 9 | J17: 103 | M17: ●
A18: IFMIBAT1003 | B18: 레버리지지수종가 | C18: 16 | D18: 시가총액 | E18: 0 | F18: Long | G18: 11 | J18: 114 | M18: ●
A19: IFMIBAT1003 | B19: 레버리지지수종가 | C19: 17 | D19: 필러값 | E19: 0 | F19: String | G19: 6 | H19: 길이 변경 | I19: 9 | J19: 120 | M19: ●
A20: IFMIBAT1004 | B20: KRX지수 현물 정규장 | C20: 1 | D20: 데이터구분값 | E20: 0 | F20: String | G20: 2 | J20: 2 | K20: A5 | M20: ●
A21: IFMIBAT1004 | B21: KRX지수 현물 정규장 | C21: 2 | D21: 시장지수구분코드 | E21: 0 | F21: String | G21: 1 | J21: 3 | K21: 0 | M21: ●
A22: IFMIBAT1004 | B22: KRX지수 현물 정규장 | C22: 3 | D22: 일련번호 | E22: 0 | F22: Int | G22: 5 | J22: 8 | M22: ●
A23: IFMIBAT1004 | B23: KRX지수 현물 정규장 | C23: 4 | D23: 영업일자 | E23: 0 | F23: String | G23: 8 | J23: 16 | M23: ●
A24: IFMIBAT1004 | B24: KRX지수 현물 정규장 | C24: 5 | D24: 지수ID | E24: 0 | F24: String | G24: 6 | H24: 신규 | J24: 22 | K24: 6자리 체계의 지수ID | M24: ●
A25: IFMIBAT1004 | B25: KRX지수 현물 정규장 | C25: 6 | D25: 단순주가평균 | E25: 0 | F25: Int | G25: 6 | J25: 28 | M25: ●
A26: IFMIBAT1004 | B26: KRX지수 현물 정규장 | C26: 7 | D26: 가중주가평균 | E26: 0 | F26: Int | G26: 6 | J26: 34 | M26: ●
A27: IFMIBAT1004 | B27: KRX지수 현물 정규장 | C27: 8 | D27: 시가지수 | E27: 0 | F27: Double | G27: 8 | J27: 42 | K27: 9(6)V9(2) | M27: ●
A28: IFMIBAT1004 | B28: KRX지수 현물 정규장 | C28: 9 | D28: 고가지수 | E28: 0 | F28: Double | G28: 8 | J28: 50 | K28: 9(6)V9(2) | M28: ●
A29: IFMIBAT1004 | B29: KRX지수 현물 정규장 | C29: 10 | D29: 저가지수 | E29: 0 | F29: Double | G29: 8 | J29: 58 | K29: 9(6)V9(2) | M29: ●
A30: IFMIBAT1004 | B30: KRX지수 현물 정규장 | C30: 11 | D30: 종가지수 | E30: 0 | F30: Double | G30: 8 | J30: 66 | K30: 9(6)V9(2) | M30: ●
A31: IFMIBAT1004 | B31: KRX지수 현물 정규장 | C31: 12 | D31: 전일지수 | E31: 0 | F31: Double | G31: 8 | J31: 74 | K31: 9(6)V9(2) | M31: ●
A32: IFMIBAT1004 | B32: KRX지수 현물 정규장 | C32: 13 | D32: 체결수량 | E32: 0 | F32: Int | G32: 8 | J32: 82 | M32: ●
A33: IFMIBAT1004 | B33: KRX지수 현물 정규장 | C33: 14 | D33: 누적거래대금 | E33: 0 | F33: Long | G33: 12 | J33: 94 | M33: ●
A34: IFMIBAT1004 | B34: KRX지수 현물 정규장 | C34: 15 | D34: 상장주식수 | E34: 0 | F34: Int | G34: 9 | J34: 103 | M34: ●
A35: IFMIBAT1004 | B35: KRX지수 현물 정규장 | C35: 16 | D35: 시가총액 | E35: 0 | F35: Long | G35: 11 | J35: 114 | M35: ●
A36: IFMIBAT1004 | B36: KRX지수 현물 정규장 | C36: 17 | D36: 필러값6 | E36: 0 | F36: String | G36: 6 | H36: 길이 변경 | I36: 9 | J36: 120 | M36: ●
A37: IFMIBAT1005 | B37: KRX지수 레버리지지수 | C37: 1 | D37: 데이터구분값 | E37: 0 | F37: String | G37: 2 | J37: 2 | K37: A5 | M37: ●
A38: IFMIBAT1005 | B38: KRX지수 레버리지지수 | C38: 2 | D38: 시장지수구분코드 | E38: 0 | F38: String | G38: 1 | J38: 3 | K38: 0 | M38: ●
A39: IFMIBAT1005 | B39: KRX지수 레버리지지수 | C39: 3 | D39: 일련번호 | E39: 0 | F39: Int | G39: 5 | J39: 8 | M39: ●
A40: IFMIBAT1005 | B40: KRX지수 레버리지지수 | C40: 4 | D40: 영업일자 | E40: 0 | F40: String | G40: 8 | J40: 16 | M40: ●
A41: IFMIBAT1005 | B41: KRX지수 레버리지지수 | C41: 5 | D41: 지수ID | E41: 0 | F41: String | G41: 6 | H41: 신규 | J41: 22 | K41: 6자리 체계의 지수ID | M41: ●
...
